{
  "nbformat": 4,
  "nbformat_minor": 0,
  "metadata": {
    "colab": {
      "provenance": []
    },
    "kernelspec": {
      "name": "python3",
      "display_name": "Python 3"
    },
    "language_info": {
      "name": "python"
    }
  },
  "cells": [
    {
      "cell_type": "code",
      "execution_count": 1,
      "metadata": {
        "colab": {
          "base_uri": "https://localhost:8080/"
        },
        "id": "aCVQvXIMCVrQ",
        "outputId": "acfed0a1-639f-451d-c3f8-65e449deab1c"
      },
      "outputs": [
        {
          "output_type": "stream",
          "name": "stdout",
          "text": [
            "Collecting streamlit\n",
            "  Downloading streamlit-1.33.0-py2.py3-none-any.whl (8.1 MB)\n",
            "\u001b[2K     \u001b[90m━━━━━━━━━━━━━━━━━━━━━━━━━━━━━━━━━━━━━━━━\u001b[0m \u001b[32m8.1/8.1 MB\u001b[0m \u001b[31m25.6 MB/s\u001b[0m eta \u001b[36m0:00:00\u001b[0m\n",
            "\u001b[?25hRequirement already satisfied: altair<6,>=4.0 in /usr/local/lib/python3.10/dist-packages (from streamlit) (4.2.2)\n",
            "Requirement already satisfied: blinker<2,>=1.0.0 in /usr/lib/python3/dist-packages (from streamlit) (1.4)\n",
            "Requirement already satisfied: cachetools<6,>=4.0 in /usr/local/lib/python3.10/dist-packages (from streamlit) (5.3.3)\n",
            "Requirement already satisfied: click<9,>=7.0 in /usr/local/lib/python3.10/dist-packages (from streamlit) (8.1.7)\n",
            "Requirement already satisfied: numpy<2,>=1.19.3 in /usr/local/lib/python3.10/dist-packages (from streamlit) (1.25.2)\n",
            "Requirement already satisfied: packaging<25,>=16.8 in /usr/local/lib/python3.10/dist-packages (from streamlit) (24.0)\n",
            "Requirement already satisfied: pandas<3,>=1.3.0 in /usr/local/lib/python3.10/dist-packages (from streamlit) (2.0.3)\n",
            "Requirement already satisfied: pillow<11,>=7.1.0 in /usr/local/lib/python3.10/dist-packages (from streamlit) (9.4.0)\n",
            "Requirement already satisfied: protobuf<5,>=3.20 in /usr/local/lib/python3.10/dist-packages (from streamlit) (3.20.3)\n",
            "Requirement already satisfied: pyarrow>=7.0 in /usr/local/lib/python3.10/dist-packages (from streamlit) (14.0.2)\n",
            "Requirement already satisfied: requests<3,>=2.27 in /usr/local/lib/python3.10/dist-packages (from streamlit) (2.31.0)\n",
            "Requirement already satisfied: rich<14,>=10.14.0 in /usr/local/lib/python3.10/dist-packages (from streamlit) (13.7.1)\n",
            "Requirement already satisfied: tenacity<9,>=8.1.0 in /usr/local/lib/python3.10/dist-packages (from streamlit) (8.2.3)\n",
            "Requirement already satisfied: toml<2,>=0.10.1 in /usr/local/lib/python3.10/dist-packages (from streamlit) (0.10.2)\n",
            "Requirement already satisfied: typing-extensions<5,>=4.3.0 in /usr/local/lib/python3.10/dist-packages (from streamlit) (4.11.0)\n",
            "Collecting gitpython!=3.1.19,<4,>=3.0.7 (from streamlit)\n",
            "  Downloading GitPython-3.1.43-py3-none-any.whl (207 kB)\n",
            "\u001b[2K     \u001b[90m━━━━━━━━━━━━━━━━━━━━━━━━━━━━━━━━━━━━━━━━\u001b[0m \u001b[32m207.3/207.3 kB\u001b[0m \u001b[31m15.3 MB/s\u001b[0m eta \u001b[36m0:00:00\u001b[0m\n",
            "\u001b[?25hCollecting pydeck<1,>=0.8.0b4 (from streamlit)\n",
            "  Downloading pydeck-0.8.1b0-py2.py3-none-any.whl (4.8 MB)\n",
            "\u001b[2K     \u001b[90m━━━━━━━━━━━━━━━━━━━━━━━━━━━━━━━━━━━━━━━━\u001b[0m \u001b[32m4.8/4.8 MB\u001b[0m \u001b[31m48.5 MB/s\u001b[0m eta \u001b[36m0:00:00\u001b[0m\n",
            "\u001b[?25hRequirement already satisfied: tornado<7,>=6.0.3 in /usr/local/lib/python3.10/dist-packages (from streamlit) (6.3.3)\n",
            "Collecting watchdog>=2.1.5 (from streamlit)\n",
            "  Downloading watchdog-4.0.0-py3-none-manylinux2014_x86_64.whl (82 kB)\n",
            "\u001b[2K     \u001b[90m━━━━━━━━━━━━━━━━━━━━━━━━━━━━━━━━━━━━━━━━\u001b[0m \u001b[32m83.0/83.0 kB\u001b[0m \u001b[31m8.3 MB/s\u001b[0m eta \u001b[36m0:00:00\u001b[0m\n",
            "\u001b[?25hRequirement already satisfied: entrypoints in /usr/local/lib/python3.10/dist-packages (from altair<6,>=4.0->streamlit) (0.4)\n",
            "Requirement already satisfied: jinja2 in /usr/local/lib/python3.10/dist-packages (from altair<6,>=4.0->streamlit) (3.1.3)\n",
            "Requirement already satisfied: jsonschema>=3.0 in /usr/local/lib/python3.10/dist-packages (from altair<6,>=4.0->streamlit) (4.19.2)\n",
            "Requirement already satisfied: toolz in /usr/local/lib/python3.10/dist-packages (from altair<6,>=4.0->streamlit) (0.12.1)\n",
            "Collecting gitdb<5,>=4.0.1 (from gitpython!=3.1.19,<4,>=3.0.7->streamlit)\n",
            "  Downloading gitdb-4.0.11-py3-none-any.whl (62 kB)\n",
            "\u001b[2K     \u001b[90m━━━━━━━━━━━━━━━━━━━━━━━━━━━━━━━━━━━━━━━━\u001b[0m \u001b[32m62.7/62.7 kB\u001b[0m \u001b[31m4.3 MB/s\u001b[0m eta \u001b[36m0:00:00\u001b[0m\n",
            "\u001b[?25hRequirement already satisfied: python-dateutil>=2.8.2 in /usr/local/lib/python3.10/dist-packages (from pandas<3,>=1.3.0->streamlit) (2.8.2)\n",
            "Requirement already satisfied: pytz>=2020.1 in /usr/local/lib/python3.10/dist-packages (from pandas<3,>=1.3.0->streamlit) (2023.4)\n",
            "Requirement already satisfied: tzdata>=2022.1 in /usr/local/lib/python3.10/dist-packages (from pandas<3,>=1.3.0->streamlit) (2024.1)\n",
            "Requirement already satisfied: charset-normalizer<4,>=2 in /usr/local/lib/python3.10/dist-packages (from requests<3,>=2.27->streamlit) (3.3.2)\n",
            "Requirement already satisfied: idna<4,>=2.5 in /usr/local/lib/python3.10/dist-packages (from requests<3,>=2.27->streamlit) (3.6)\n",
            "Requirement already satisfied: urllib3<3,>=1.21.1 in /usr/local/lib/python3.10/dist-packages (from requests<3,>=2.27->streamlit) (2.0.7)\n",
            "Requirement already satisfied: certifi>=2017.4.17 in /usr/local/lib/python3.10/dist-packages (from requests<3,>=2.27->streamlit) (2024.2.2)\n",
            "Requirement already satisfied: markdown-it-py>=2.2.0 in /usr/local/lib/python3.10/dist-packages (from rich<14,>=10.14.0->streamlit) (3.0.0)\n",
            "Requirement already satisfied: pygments<3.0.0,>=2.13.0 in /usr/local/lib/python3.10/dist-packages (from rich<14,>=10.14.0->streamlit) (2.16.1)\n",
            "Collecting smmap<6,>=3.0.1 (from gitdb<5,>=4.0.1->gitpython!=3.1.19,<4,>=3.0.7->streamlit)\n",
            "  Downloading smmap-5.0.1-py3-none-any.whl (24 kB)\n",
            "Requirement already satisfied: MarkupSafe>=2.0 in /usr/local/lib/python3.10/dist-packages (from jinja2->altair<6,>=4.0->streamlit) (2.1.5)\n",
            "Requirement already satisfied: attrs>=22.2.0 in /usr/local/lib/python3.10/dist-packages (from jsonschema>=3.0->altair<6,>=4.0->streamlit) (23.2.0)\n",
            "Requirement already satisfied: jsonschema-specifications>=2023.03.6 in /usr/local/lib/python3.10/dist-packages (from jsonschema>=3.0->altair<6,>=4.0->streamlit) (2023.12.1)\n",
            "Requirement already satisfied: referencing>=0.28.4 in /usr/local/lib/python3.10/dist-packages (from jsonschema>=3.0->altair<6,>=4.0->streamlit) (0.34.0)\n",
            "Requirement already satisfied: rpds-py>=0.7.1 in /usr/local/lib/python3.10/dist-packages (from jsonschema>=3.0->altair<6,>=4.0->streamlit) (0.18.0)\n",
            "Requirement already satisfied: mdurl~=0.1 in /usr/local/lib/python3.10/dist-packages (from markdown-it-py>=2.2.0->rich<14,>=10.14.0->streamlit) (0.1.2)\n",
            "Requirement already satisfied: six>=1.5 in /usr/local/lib/python3.10/dist-packages (from python-dateutil>=2.8.2->pandas<3,>=1.3.0->streamlit) (1.16.0)\n",
            "Installing collected packages: watchdog, smmap, pydeck, gitdb, gitpython, streamlit\n",
            "Successfully installed gitdb-4.0.11 gitpython-3.1.43 pydeck-0.8.1b0 smmap-5.0.1 streamlit-1.33.0 watchdog-4.0.0\n"
          ]
        }
      ],
      "source": [
        "pip install streamlit"
      ]
    },
    {
      "cell_type": "code",
      "source": [
        "%%writefile app.py"
      ],
      "metadata": {
        "colab": {
          "base_uri": "https://localhost:8080/"
        },
        "id": "6Gb6dv0fCuqm",
        "outputId": "d3db29e6-d76b-42cb-c735-30bd12f8ac54"
      },
      "execution_count": 2,
      "outputs": [
        {
          "output_type": "stream",
          "name": "stdout",
          "text": [
            "Writing app.py\n"
          ]
        }
      ]
    },
    {
      "cell_type": "code",
      "source": [
        "! wget -q -O - ipv4.icanhazip.com"
      ],
      "metadata": {
        "colab": {
          "base_uri": "https://localhost:8080/"
        },
        "id": "C4fsK2YoCiA8",
        "outputId": "2ee2dcef-4065-4fc4-e164-ee4efd19ff90"
      },
      "execution_count": 3,
      "outputs": [
        {
          "output_type": "stream",
          "name": "stdout",
          "text": [
            "34.147.69.1\n"
          ]
        }
      ]
    },
    {
      "cell_type": "code",
      "source": [
        "! streamlit run app.py & npx localtunnel --port 8501"
      ],
      "metadata": {
        "colab": {
          "base_uri": "https://localhost:8080/"
        },
        "id": "if-eqTioDEWe",
        "outputId": "6720175f-33d0-4292-8abc-fdb4870db318"
      },
      "execution_count": null,
      "outputs": [
        {
          "output_type": "stream",
          "name": "stdout",
          "text": [
            "\n",
            "Collecting usage statistics. To deactivate, set browser.gatherUsageStats to false.\n",
            "\u001b[0m\n",
            "\u001b[0m\n",
            "\u001b[34m\u001b[1m  You can now view your Streamlit app in your browser.\u001b[0m\n",
            "\u001b[0m\n",
            "\u001b[34m  Network URL: \u001b[0m\u001b[1mhttp://172.28.0.12:8501\u001b[0m\n",
            "\u001b[34m  External URL: \u001b[0m\u001b[1mhttp://34.147.69.1:8501\u001b[0m\n",
            "\u001b[0m\n",
            "\u001b[K\u001b[?25hnpx: installed 22 in 3.763s\n",
            "your url is: https://fresh-crabs-dress.loca.lt\n",
            "2024-04-11 21:40:36.091 Uncaught app exception\n",
            "Traceback (most recent call last):\n",
            "  File \"/usr/local/lib/python3.10/dist-packages/streamlit/runtime/scriptrunner/script_runner.py\", line 584, in _run_script\n",
            "    exec(code, module.__dict__)\n",
            "  File \"/content/app.py\", line 29, in <module>\n",
            "    output = api_calling(user_input)\n",
            "  File \"/content/app.py\", line 9, in api_calling\n",
            "    completions = openai.Completion.create(\n",
            "  File \"/usr/local/lib/python3.10/dist-packages/openai/api_resources/completion.py\", line 25, in create\n",
            "    return super().create(*args, **kwargs)\n",
            "  File \"/usr/local/lib/python3.10/dist-packages/openai/api_resources/abstract/engine_api_resource.py\", line 153, in create\n",
            "    response, _, api_key = requestor.request(\n",
            "  File \"/usr/local/lib/python3.10/dist-packages/openai/api_requestor.py\", line 298, in request\n",
            "    resp, got_stream = self._interpret_response(result, stream)\n",
            "  File \"/usr/local/lib/python3.10/dist-packages/openai/api_requestor.py\", line 700, in _interpret_response\n",
            "    self._interpret_response_line(\n",
            "  File \"/usr/local/lib/python3.10/dist-packages/openai/api_requestor.py\", line 765, in _interpret_response_line\n",
            "    raise self.handle_error_response(\n",
            "openai.error.InvalidRequestError: The model `text-davinci-003` has been deprecated, learn more here: https://platform.openai.com/docs/deprecations\n",
            "2024-04-11 21:41:44.225 Uncaught app exception\n",
            "Traceback (most recent call last):\n",
            "  File \"/usr/local/lib/python3.10/dist-packages/streamlit/runtime/scriptrunner/script_runner.py\", line 584, in _run_script\n",
            "    exec(code, module.__dict__)\n",
            "  File \"/content/app.py\", line 72, in <module>\n",
            "    output = api_calling(user_input)\n",
            "  File \"/content/app.py\", line 56, in api_calling\n",
            "    completions = openai.Completion.create(\n",
            "  File \"/usr/local/lib/python3.10/dist-packages/openai/api_resources/completion.py\", line 25, in create\n",
            "    return super().create(*args, **kwargs)\n",
            "  File \"/usr/local/lib/python3.10/dist-packages/openai/api_resources/abstract/engine_api_resource.py\", line 153, in create\n",
            "    response, _, api_key = requestor.request(\n",
            "  File \"/usr/local/lib/python3.10/dist-packages/openai/api_requestor.py\", line 298, in request\n",
            "    resp, got_stream = self._interpret_response(result, stream)\n",
            "  File \"/usr/local/lib/python3.10/dist-packages/openai/api_requestor.py\", line 700, in _interpret_response\n",
            "    self._interpret_response_line(\n",
            "  File \"/usr/local/lib/python3.10/dist-packages/openai/api_requestor.py\", line 765, in _interpret_response_line\n",
            "    raise self.handle_error_response(\n",
            "openai.error.InvalidRequestError: The model `text-davinci` does not exist or you do not have access to it.\n",
            "2024-04-11 21:43:01.697 Uncaught app exception\n",
            "Traceback (most recent call last):\n",
            "  File \"/usr/local/lib/python3.10/dist-packages/streamlit/runtime/scriptrunner/script_runner.py\", line 584, in _run_script\n",
            "    exec(code, module.__dict__)\n",
            "  File \"/content/app.py\", line 81, in <module>\n",
            "    output = api_calling(user_input)\n",
            "  File \"/content/app.py\", line 63, in api_calling\n",
            "    completions = openai.Completion.create(\n",
            "  File \"/usr/local/lib/python3.10/dist-packages/openai/api_resources/completion.py\", line 25, in create\n",
            "    return super().create(*args, **kwargs)\n",
            "  File \"/usr/local/lib/python3.10/dist-packages/openai/api_resources/abstract/engine_api_resource.py\", line 153, in create\n",
            "    response, _, api_key = requestor.request(\n",
            "  File \"/usr/local/lib/python3.10/dist-packages/openai/api_requestor.py\", line 298, in request\n",
            "    resp, got_stream = self._interpret_response(result, stream)\n",
            "  File \"/usr/local/lib/python3.10/dist-packages/openai/api_requestor.py\", line 700, in _interpret_response\n",
            "    self._interpret_response_line(\n",
            "  File \"/usr/local/lib/python3.10/dist-packages/openai/api_requestor.py\", line 765, in _interpret_response_line\n",
            "    raise self.handle_error_response(\n",
            "openai.error.InvalidRequestError: The model `text-davinci-codex` does not exist or you do not have access to it.\n",
            "2024-04-11 21:43:55.446 Uncaught app exception\n",
            "Traceback (most recent call last):\n",
            "  File \"/usr/local/lib/python3.10/dist-packages/streamlit/runtime/scriptrunner/script_runner.py\", line 584, in _run_script\n",
            "    exec(code, module.__dict__)\n",
            "  File \"/content/app.py\", line 81, in <module>\n",
            "    output = api_calling(user_input)\n",
            "  File \"/content/app.py\", line 63, in api_calling\n",
            "    completions = openai.Completion.create(\n",
            "  File \"/usr/local/lib/python3.10/dist-packages/openai/api_resources/completion.py\", line 25, in create\n",
            "    return super().create(*args, **kwargs)\n",
            "  File \"/usr/local/lib/python3.10/dist-packages/openai/api_resources/abstract/engine_api_resource.py\", line 153, in create\n",
            "    response, _, api_key = requestor.request(\n",
            "  File \"/usr/local/lib/python3.10/dist-packages/openai/api_requestor.py\", line 298, in request\n",
            "    resp, got_stream = self._interpret_response(result, stream)\n",
            "  File \"/usr/local/lib/python3.10/dist-packages/openai/api_requestor.py\", line 700, in _interpret_response\n",
            "    self._interpret_response_line(\n",
            "  File \"/usr/local/lib/python3.10/dist-packages/openai/api_requestor.py\", line 765, in _interpret_response_line\n",
            "    raise self.handle_error_response(\n",
            "openai.error.InvalidRequestError: The model `text-davinci-003` has been deprecated, learn more here: https://platform.openai.com/docs/deprecations\n",
            "2024-04-11 21:44:47.909 Uncaught app exception\n",
            "Traceback (most recent call last):\n",
            "  File \"/usr/local/lib/python3.10/dist-packages/streamlit/runtime/scriptrunner/script_runner.py\", line 584, in _run_script\n",
            "    exec(code, module.__dict__)\n",
            "  File \"/content/app.py\", line 81, in <module>\n",
            "    output = api_calling(user_input)\n",
            "  File \"/content/app.py\", line 63, in api_calling\n",
            "    completions = openai.Completion.create(\n",
            "  File \"/usr/local/lib/python3.10/dist-packages/openai/api_resources/completion.py\", line 25, in create\n",
            "    return super().create(*args, **kwargs)\n",
            "  File \"/usr/local/lib/python3.10/dist-packages/openai/api_resources/abstract/engine_api_resource.py\", line 153, in create\n",
            "    response, _, api_key = requestor.request(\n",
            "  File \"/usr/local/lib/python3.10/dist-packages/openai/api_requestor.py\", line 298, in request\n",
            "    resp, got_stream = self._interpret_response(result, stream)\n",
            "  File \"/usr/local/lib/python3.10/dist-packages/openai/api_requestor.py\", line 700, in _interpret_response\n",
            "    self._interpret_response_line(\n",
            "  File \"/usr/local/lib/python3.10/dist-packages/openai/api_requestor.py\", line 765, in _interpret_response_line\n",
            "    raise self.handle_error_response(\n",
            "openai.error.InvalidRequestError: The model `davinci-codex` has been deprecated, learn more here: https://platform.openai.com/docs/deprecations\n",
            "2024-04-11 21:45:38.615 Uncaught app exception\n",
            "Traceback (most recent call last):\n",
            "  File \"/usr/local/lib/python3.10/dist-packages/streamlit/runtime/scriptrunner/script_runner.py\", line 584, in _run_script\n",
            "    exec(code, module.__dict__)\n",
            "  File \"/content/app.py\", line 81, in <module>\n",
            "    output = api_calling(user_input)\n",
            "  File \"/content/app.py\", line 63, in api_calling\n",
            "    completions = openai.Completion.create(\n",
            "  File \"/usr/local/lib/python3.10/dist-packages/openai/api_resources/completion.py\", line 25, in create\n",
            "    return super().create(*args, **kwargs)\n",
            "  File \"/usr/local/lib/python3.10/dist-packages/openai/api_resources/abstract/engine_api_resource.py\", line 153, in create\n",
            "    response, _, api_key = requestor.request(\n",
            "  File \"/usr/local/lib/python3.10/dist-packages/openai/api_requestor.py\", line 298, in request\n",
            "    resp, got_stream = self._interpret_response(result, stream)\n",
            "  File \"/usr/local/lib/python3.10/dist-packages/openai/api_requestor.py\", line 700, in _interpret_response\n",
            "    self._interpret_response_line(\n",
            "  File \"/usr/local/lib/python3.10/dist-packages/openai/api_requestor.py\", line 765, in _interpret_response_line\n",
            "    raise self.handle_error_response(\n",
            "openai.error.RateLimitError: You exceeded your current quota, please check your plan and billing details. For more information on this error, read the docs: https://platform.openai.com/docs/guides/error-codes/api-errors.\n",
            "2024-04-11 21:52:45.829 Uncaught app exception\n",
            "Traceback (most recent call last):\n",
            "  File \"/usr/local/lib/python3.10/dist-packages/streamlit/runtime/scriptrunner/script_runner.py\", line 584, in _run_script\n",
            "    exec(code, module.__dict__)\n",
            "  File \"/content/app.py\", line 80, in <module>\n",
            "    output = api_calling(user_input)\n",
            "  File \"/content/app.py\", line 62, in api_calling\n",
            "    completions = openai.Completion.create(\n",
            "  File \"/usr/local/lib/python3.10/dist-packages/openai/api_resources/completion.py\", line 25, in create\n",
            "    return super().create(*args, **kwargs)\n",
            "  File \"/usr/local/lib/python3.10/dist-packages/openai/api_resources/abstract/engine_api_resource.py\", line 153, in create\n",
            "    response, _, api_key = requestor.request(\n",
            "  File \"/usr/local/lib/python3.10/dist-packages/openai/api_requestor.py\", line 298, in request\n",
            "    resp, got_stream = self._interpret_response(result, stream)\n",
            "  File \"/usr/local/lib/python3.10/dist-packages/openai/api_requestor.py\", line 700, in _interpret_response\n",
            "    self._interpret_response_line(\n",
            "  File \"/usr/local/lib/python3.10/dist-packages/openai/api_requestor.py\", line 765, in _interpret_response_line\n",
            "    raise self.handle_error_response(\n",
            "openai.error.InvalidRequestError: The model `text-babbage` does not exist or you do not have access to it.\n",
            "2024-04-11 21:53:58.737 Uncaught app exception\n",
            "Traceback (most recent call last):\n",
            "  File \"/usr/local/lib/python3.10/dist-packages/streamlit/runtime/scriptrunner/script_runner.py\", line 584, in _run_script\n",
            "    exec(code, module.__dict__)\n",
            "  File \"/content/app.py\", line 80, in <module>\n",
            "    output = api_calling(user_input)\n",
            "  File \"/content/app.py\", line 62, in api_calling\n",
            "    completions = openai.Completion.create(\n",
            "  File \"/usr/local/lib/python3.10/dist-packages/openai/api_resources/completion.py\", line 25, in create\n",
            "    return super().create(*args, **kwargs)\n",
            "  File \"/usr/local/lib/python3.10/dist-packages/openai/api_resources/abstract/engine_api_resource.py\", line 153, in create\n",
            "    response, _, api_key = requestor.request(\n",
            "  File \"/usr/local/lib/python3.10/dist-packages/openai/api_requestor.py\", line 298, in request\n",
            "    resp, got_stream = self._interpret_response(result, stream)\n",
            "  File \"/usr/local/lib/python3.10/dist-packages/openai/api_requestor.py\", line 700, in _interpret_response\n",
            "    self._interpret_response_line(\n",
            "  File \"/usr/local/lib/python3.10/dist-packages/openai/api_requestor.py\", line 765, in _interpret_response_line\n",
            "    raise self.handle_error_response(\n",
            "openai.error.InvalidRequestError: The model `text-gpt-3.5-turbo-v1` does not exist or you do not have access to it.\n",
            "2024-04-11 21:54:22.953 Uncaught app exception\n",
            "Traceback (most recent call last):\n",
            "  File \"/usr/local/lib/python3.10/dist-packages/streamlit/runtime/scriptrunner/script_runner.py\", line 584, in _run_script\n",
            "    exec(code, module.__dict__)\n",
            "  File \"/content/app.py\", line 80, in <module>\n",
            "    output = api_calling(user_input)\n",
            "  File \"/content/app.py\", line 62, in api_calling\n",
            "    completions = openai.Completion.create(\n",
            "  File \"/usr/local/lib/python3.10/dist-packages/openai/api_resources/completion.py\", line 25, in create\n",
            "    return super().create(*args, **kwargs)\n",
            "  File \"/usr/local/lib/python3.10/dist-packages/openai/api_resources/abstract/engine_api_resource.py\", line 153, in create\n",
            "    response, _, api_key = requestor.request(\n",
            "  File \"/usr/local/lib/python3.10/dist-packages/openai/api_requestor.py\", line 298, in request\n",
            "    resp, got_stream = self._interpret_response(result, stream)\n",
            "  File \"/usr/local/lib/python3.10/dist-packages/openai/api_requestor.py\", line 700, in _interpret_response\n",
            "    self._interpret_response_line(\n",
            "  File \"/usr/local/lib/python3.10/dist-packages/openai/api_requestor.py\", line 765, in _interpret_response_line\n",
            "    raise self.handle_error_response(\n",
            "openai.error.InvalidRequestError: The model `text-gpt-3.5-turbo-v2` does not exist or you do not have access to it.\n",
            "2024-04-11 21:55:02.751 Uncaught app exception\n",
            "Traceback (most recent call last):\n",
            "  File \"/usr/local/lib/python3.10/dist-packages/streamlit/runtime/scriptrunner/script_runner.py\", line 584, in _run_script\n",
            "    exec(code, module.__dict__)\n",
            "  File \"/content/app.py\", line 80, in <module>\n",
            "    output = api_calling(user_input)\n",
            "  File \"/content/app.py\", line 62, in api_calling\n",
            "    completions = openai.Completion.create(\n",
            "  File \"/usr/local/lib/python3.10/dist-packages/openai/api_resources/completion.py\", line 25, in create\n",
            "    return super().create(*args, **kwargs)\n",
            "  File \"/usr/local/lib/python3.10/dist-packages/openai/api_resources/abstract/engine_api_resource.py\", line 153, in create\n",
            "    response, _, api_key = requestor.request(\n",
            "  File \"/usr/local/lib/python3.10/dist-packages/openai/api_requestor.py\", line 298, in request\n",
            "    resp, got_stream = self._interpret_response(result, stream)\n",
            "  File \"/usr/local/lib/python3.10/dist-packages/openai/api_requestor.py\", line 700, in _interpret_response\n",
            "    self._interpret_response_line(\n",
            "  File \"/usr/local/lib/python3.10/dist-packages/openai/api_requestor.py\", line 765, in _interpret_response_line\n",
            "    raise self.handle_error_response(\n",
            "openai.error.InvalidRequestError: The model `text-gpt-3.5-turbo-v1.3` does not exist or you do not have access to it.\n",
            "2024-04-11 21:56:32.137 Uncaught app exception\n",
            "Traceback (most recent call last):\n",
            "  File \"/usr/local/lib/python3.10/dist-packages/streamlit/runtime/scriptrunner/script_runner.py\", line 584, in _run_script\n",
            "    exec(code, module.__dict__)\n",
            "  File \"/content/app.py\", line 80, in <module>\n",
            "    output = api_calling(user_input)\n",
            "  File \"/content/app.py\", line 62, in api_calling\n",
            "    completions = openai.Completion.create(\n",
            "  File \"/usr/local/lib/python3.10/dist-packages/openai/api_resources/completion.py\", line 25, in create\n",
            "    return super().create(*args, **kwargs)\n",
            "  File \"/usr/local/lib/python3.10/dist-packages/openai/api_resources/abstract/engine_api_resource.py\", line 153, in create\n",
            "    response, _, api_key = requestor.request(\n",
            "  File \"/usr/local/lib/python3.10/dist-packages/openai/api_requestor.py\", line 298, in request\n",
            "    resp, got_stream = self._interpret_response(result, stream)\n",
            "  File \"/usr/local/lib/python3.10/dist-packages/openai/api_requestor.py\", line 700, in _interpret_response\n",
            "    self._interpret_response_line(\n",
            "  File \"/usr/local/lib/python3.10/dist-packages/openai/api_requestor.py\", line 765, in _interpret_response_line\n",
            "    raise self.handle_error_response(\n",
            "openai.error.InvalidRequestError: The model `text-gpt-3.5-turbo` does not exist or you do not have access to it.\n",
            "2024-04-11 21:58:11.503 Uncaught app exception\n",
            "Traceback (most recent call last):\n",
            "  File \"/usr/local/lib/python3.10/dist-packages/streamlit/runtime/scriptrunner/script_runner.py\", line 584, in _run_script\n",
            "    exec(code, module.__dict__)\n",
            "  File \"/content/app.py\", line 80, in <module>\n",
            "    output = api_calling(user_input)\n",
            "  File \"/content/app.py\", line 62, in api_calling\n",
            "    completions = openai.Completion.create(\n",
            "  File \"/usr/local/lib/python3.10/dist-packages/openai/api_resources/completion.py\", line 25, in create\n",
            "    return super().create(*args, **kwargs)\n",
            "  File \"/usr/local/lib/python3.10/dist-packages/openai/api_resources/abstract/engine_api_resource.py\", line 153, in create\n",
            "    response, _, api_key = requestor.request(\n",
            "  File \"/usr/local/lib/python3.10/dist-packages/openai/api_requestor.py\", line 298, in request\n",
            "    resp, got_stream = self._interpret_response(result, stream)\n",
            "  File \"/usr/local/lib/python3.10/dist-packages/openai/api_requestor.py\", line 700, in _interpret_response\n",
            "    self._interpret_response_line(\n",
            "  File \"/usr/local/lib/python3.10/dist-packages/openai/api_requestor.py\", line 765, in _interpret_response_line\n",
            "    raise self.handle_error_response(\n",
            "openai.error.InvalidRequestError: The model `text-gpt-3.5-turbo` does not exist or you do not have access to it.\n",
            "2024-04-11 21:58:26.758 Uncaught app exception\n",
            "Traceback (most recent call last):\n",
            "  File \"/usr/local/lib/python3.10/dist-packages/streamlit/runtime/scriptrunner/script_runner.py\", line 584, in _run_script\n",
            "    exec(code, module.__dict__)\n",
            "  File \"/content/app.py\", line 80, in <module>\n",
            "    output = api_calling(user_input)\n",
            "  File \"/content/app.py\", line 62, in api_calling\n",
            "    completions = openai.Completion.create(\n",
            "  File \"/usr/local/lib/python3.10/dist-packages/openai/api_resources/completion.py\", line 25, in create\n",
            "    return super().create(*args, **kwargs)\n",
            "  File \"/usr/local/lib/python3.10/dist-packages/openai/api_resources/abstract/engine_api_resource.py\", line 153, in create\n",
            "    response, _, api_key = requestor.request(\n",
            "  File \"/usr/local/lib/python3.10/dist-packages/openai/api_requestor.py\", line 298, in request\n",
            "    resp, got_stream = self._interpret_response(result, stream)\n",
            "  File \"/usr/local/lib/python3.10/dist-packages/openai/api_requestor.py\", line 700, in _interpret_response\n",
            "    self._interpret_response_line(\n",
            "  File \"/usr/local/lib/python3.10/dist-packages/openai/api_requestor.py\", line 765, in _interpret_response_line\n",
            "    raise self.handle_error_response(\n",
            "openai.error.InvalidRequestError: The model `text-gpt-3.5-turbo` does not exist or you do not have access to it.\n"
          ]
        }
      ]
    },
    {
      "cell_type": "code",
      "source": [
        "!pip install openai\n"
      ],
      "metadata": {
        "colab": {
          "base_uri": "https://localhost:8080/"
        },
        "id": "k91r1ssEE8Tx",
        "outputId": "3e42b663-ee77-48fc-cd51-a90ae56e4e06"
      },
      "execution_count": 6,
      "outputs": [
        {
          "output_type": "stream",
          "name": "stdout",
          "text": [
            "Collecting openai\n",
            "  Downloading openai-1.17.0-py3-none-any.whl (268 kB)\n",
            "\u001b[?25l     \u001b[90m━━━━━━━━━━━━━━━━━━━━━━━━━━━━━━━━━━━━━━━━\u001b[0m \u001b[32m0.0/268.3 kB\u001b[0m \u001b[31m?\u001b[0m eta \u001b[36m-:--:--\u001b[0m\r\u001b[2K     \u001b[91m━━━━━━━━━━━━━━━━━━━━━\u001b[0m\u001b[90m╺\u001b[0m\u001b[90m━━━━━━━━━━━━━━━━━━\u001b[0m \u001b[32m143.4/268.3 kB\u001b[0m \u001b[31m4.0 MB/s\u001b[0m eta \u001b[36m0:00:01\u001b[0m\r\u001b[2K     \u001b[90m━━━━━━━━━━━━━━━━━━━━━━━━━━━━━━━━━━━━━━━━\u001b[0m \u001b[32m268.3/268.3 kB\u001b[0m \u001b[31m4.8 MB/s\u001b[0m eta \u001b[36m0:00:00\u001b[0m\n",
            "\u001b[?25hRequirement already satisfied: anyio<5,>=3.5.0 in /usr/local/lib/python3.10/dist-packages (from openai) (3.7.1)\n",
            "Requirement already satisfied: distro<2,>=1.7.0 in /usr/lib/python3/dist-packages (from openai) (1.7.0)\n",
            "Collecting httpx<1,>=0.23.0 (from openai)\n",
            "  Downloading httpx-0.27.0-py3-none-any.whl (75 kB)\n",
            "\u001b[2K     \u001b[90m━━━━━━━━━━━━━━━━━━━━━━━━━━━━━━━━━━━━━━━━\u001b[0m \u001b[32m75.6/75.6 kB\u001b[0m \u001b[31m7.2 MB/s\u001b[0m eta \u001b[36m0:00:00\u001b[0m\n",
            "\u001b[?25hRequirement already satisfied: pydantic<3,>=1.9.0 in /usr/local/lib/python3.10/dist-packages (from openai) (2.6.4)\n",
            "Requirement already satisfied: sniffio in /usr/local/lib/python3.10/dist-packages (from openai) (1.3.1)\n",
            "Requirement already satisfied: tqdm>4 in /usr/local/lib/python3.10/dist-packages (from openai) (4.66.2)\n",
            "Requirement already satisfied: typing-extensions<5,>=4.7 in /usr/local/lib/python3.10/dist-packages (from openai) (4.11.0)\n",
            "Requirement already satisfied: idna>=2.8 in /usr/local/lib/python3.10/dist-packages (from anyio<5,>=3.5.0->openai) (3.6)\n",
            "Requirement already satisfied: exceptiongroup in /usr/local/lib/python3.10/dist-packages (from anyio<5,>=3.5.0->openai) (1.2.0)\n",
            "Requirement already satisfied: certifi in /usr/local/lib/python3.10/dist-packages (from httpx<1,>=0.23.0->openai) (2024.2.2)\n",
            "Collecting httpcore==1.* (from httpx<1,>=0.23.0->openai)\n",
            "  Downloading httpcore-1.0.5-py3-none-any.whl (77 kB)\n",
            "\u001b[2K     \u001b[90m━━━━━━━━━━━━━━━━━━━━━━━━━━━━━━━━━━━━━━━━\u001b[0m \u001b[32m77.9/77.9 kB\u001b[0m \u001b[31m9.1 MB/s\u001b[0m eta \u001b[36m0:00:00\u001b[0m\n",
            "\u001b[?25hCollecting h11<0.15,>=0.13 (from httpcore==1.*->httpx<1,>=0.23.0->openai)\n",
            "  Downloading h11-0.14.0-py3-none-any.whl (58 kB)\n",
            "\u001b[2K     \u001b[90m━━━━━━━━━━━━━━━━━━━━━━━━━━━━━━━━━━━━━━━━\u001b[0m \u001b[32m58.3/58.3 kB\u001b[0m \u001b[31m6.5 MB/s\u001b[0m eta \u001b[36m0:00:00\u001b[0m\n",
            "\u001b[?25hRequirement already satisfied: annotated-types>=0.4.0 in /usr/local/lib/python3.10/dist-packages (from pydantic<3,>=1.9.0->openai) (0.6.0)\n",
            "Requirement already satisfied: pydantic-core==2.16.3 in /usr/local/lib/python3.10/dist-packages (from pydantic<3,>=1.9.0->openai) (2.16.3)\n",
            "Installing collected packages: h11, httpcore, httpx, openai\n",
            "Successfully installed h11-0.14.0 httpcore-1.0.5 httpx-0.27.0 openai-1.17.0\n"
          ]
        }
      ]
    },
    {
      "cell_type": "code",
      "source": [
        "!pip install openai==0.28"
      ],
      "metadata": {
        "colab": {
          "base_uri": "https://localhost:8080/",
          "height": 516
        },
        "id": "zhKreRL5GiiR",
        "outputId": "fa868632-95df-4764-a05c-10ba8ca98187"
      },
      "execution_count": 15,
      "outputs": [
        {
          "output_type": "stream",
          "name": "stdout",
          "text": [
            "Collecting openai==0.28\n",
            "  Downloading openai-0.28.0-py3-none-any.whl (76 kB)\n",
            "\u001b[?25l     \u001b[90m━━━━━━━━━━━━━━━━━━━━━━━━━━━━━━━━━━━━━━━━\u001b[0m \u001b[32m0.0/76.5 kB\u001b[0m \u001b[31m?\u001b[0m eta \u001b[36m-:--:--\u001b[0m\r\u001b[2K     \u001b[90m━━━━━━━━━━━━━━━━━━━━━━━━━━━━━━━━━━━━━━━━\u001b[0m \u001b[32m76.5/76.5 kB\u001b[0m \u001b[31m2.8 MB/s\u001b[0m eta \u001b[36m0:00:00\u001b[0m\n",
            "\u001b[?25hRequirement already satisfied: requests>=2.20 in /usr/local/lib/python3.10/dist-packages (from openai==0.28) (2.31.0)\n",
            "Requirement already satisfied: tqdm in /usr/local/lib/python3.10/dist-packages (from openai==0.28) (4.66.2)\n",
            "Requirement already satisfied: aiohttp in /usr/local/lib/python3.10/dist-packages (from openai==0.28) (3.9.3)\n",
            "Requirement already satisfied: charset-normalizer<4,>=2 in /usr/local/lib/python3.10/dist-packages (from requests>=2.20->openai==0.28) (3.3.2)\n",
            "Requirement already satisfied: idna<4,>=2.5 in /usr/local/lib/python3.10/dist-packages (from requests>=2.20->openai==0.28) (3.6)\n",
            "Requirement already satisfied: urllib3<3,>=1.21.1 in /usr/local/lib/python3.10/dist-packages (from requests>=2.20->openai==0.28) (2.0.7)\n",
            "Requirement already satisfied: certifi>=2017.4.17 in /usr/local/lib/python3.10/dist-packages (from requests>=2.20->openai==0.28) (2024.2.2)\n",
            "Requirement already satisfied: aiosignal>=1.1.2 in /usr/local/lib/python3.10/dist-packages (from aiohttp->openai==0.28) (1.3.1)\n",
            "Requirement already satisfied: attrs>=17.3.0 in /usr/local/lib/python3.10/dist-packages (from aiohttp->openai==0.28) (23.2.0)\n",
            "Requirement already satisfied: frozenlist>=1.1.1 in /usr/local/lib/python3.10/dist-packages (from aiohttp->openai==0.28) (1.4.1)\n",
            "Requirement already satisfied: multidict<7.0,>=4.5 in /usr/local/lib/python3.10/dist-packages (from aiohttp->openai==0.28) (6.0.5)\n",
            "Requirement already satisfied: yarl<2.0,>=1.0 in /usr/local/lib/python3.10/dist-packages (from aiohttp->openai==0.28) (1.9.4)\n",
            "Requirement already satisfied: async-timeout<5.0,>=4.0 in /usr/local/lib/python3.10/dist-packages (from aiohttp->openai==0.28) (4.0.3)\n",
            "Installing collected packages: openai\n",
            "  Attempting uninstall: openai\n",
            "    Found existing installation: openai 1.17.0\n",
            "    Uninstalling openai-1.17.0:\n",
            "      Successfully uninstalled openai-1.17.0\n",
            "Successfully installed openai-0.28.0\n"
          ]
        },
        {
          "output_type": "display_data",
          "data": {
            "application/vnd.colab-display-data+json": {
              "pip_warning": {
                "packages": [
                  "openai"
                ]
              },
              "id": "781dd79a99ff4482bd8be5d17b7014d0"
            }
          },
          "metadata": {}
        }
      ]
    },
    {
      "cell_type": "code",
      "source": [
        "!pip install streamlit_chat\n"
      ],
      "metadata": {
        "colab": {
          "base_uri": "https://localhost:8080/"
        },
        "id": "r2vfUL9rFIqf",
        "outputId": "1e4ceb9a-bad6-45ba-e9b9-bf8ff55c808c"
      },
      "execution_count": 8,
      "outputs": [
        {
          "output_type": "stream",
          "name": "stdout",
          "text": [
            "Collecting streamlit_chat\n",
            "  Downloading streamlit_chat-0.1.1-py3-none-any.whl (1.2 MB)\n",
            "\u001b[2K     \u001b[90m━━━━━━━━━━━━━━━━━━━━━━━━━━━━━━━━━━━━━━━━\u001b[0m \u001b[32m1.2/1.2 MB\u001b[0m \u001b[31m7.6 MB/s\u001b[0m eta \u001b[36m0:00:00\u001b[0m\n",
            "\u001b[?25hRequirement already satisfied: streamlit>=0.63 in /usr/local/lib/python3.10/dist-packages (from streamlit_chat) (1.33.0)\n",
            "Requirement already satisfied: altair<6,>=4.0 in /usr/local/lib/python3.10/dist-packages (from streamlit>=0.63->streamlit_chat) (4.2.2)\n",
            "Requirement already satisfied: blinker<2,>=1.0.0 in /usr/lib/python3/dist-packages (from streamlit>=0.63->streamlit_chat) (1.4)\n",
            "Requirement already satisfied: cachetools<6,>=4.0 in /usr/local/lib/python3.10/dist-packages (from streamlit>=0.63->streamlit_chat) (5.3.3)\n",
            "Requirement already satisfied: click<9,>=7.0 in /usr/local/lib/python3.10/dist-packages (from streamlit>=0.63->streamlit_chat) (8.1.7)\n",
            "Requirement already satisfied: numpy<2,>=1.19.3 in /usr/local/lib/python3.10/dist-packages (from streamlit>=0.63->streamlit_chat) (1.25.2)\n",
            "Requirement already satisfied: packaging<25,>=16.8 in /usr/local/lib/python3.10/dist-packages (from streamlit>=0.63->streamlit_chat) (24.0)\n",
            "Requirement already satisfied: pandas<3,>=1.3.0 in /usr/local/lib/python3.10/dist-packages (from streamlit>=0.63->streamlit_chat) (2.0.3)\n",
            "Requirement already satisfied: pillow<11,>=7.1.0 in /usr/local/lib/python3.10/dist-packages (from streamlit>=0.63->streamlit_chat) (9.4.0)\n",
            "Requirement already satisfied: protobuf<5,>=3.20 in /usr/local/lib/python3.10/dist-packages (from streamlit>=0.63->streamlit_chat) (3.20.3)\n",
            "Requirement already satisfied: pyarrow>=7.0 in /usr/local/lib/python3.10/dist-packages (from streamlit>=0.63->streamlit_chat) (14.0.2)\n",
            "Requirement already satisfied: requests<3,>=2.27 in /usr/local/lib/python3.10/dist-packages (from streamlit>=0.63->streamlit_chat) (2.31.0)\n",
            "Requirement already satisfied: rich<14,>=10.14.0 in /usr/local/lib/python3.10/dist-packages (from streamlit>=0.63->streamlit_chat) (13.7.1)\n",
            "Requirement already satisfied: tenacity<9,>=8.1.0 in /usr/local/lib/python3.10/dist-packages (from streamlit>=0.63->streamlit_chat) (8.2.3)\n",
            "Requirement already satisfied: toml<2,>=0.10.1 in /usr/local/lib/python3.10/dist-packages (from streamlit>=0.63->streamlit_chat) (0.10.2)\n",
            "Requirement already satisfied: typing-extensions<5,>=4.3.0 in /usr/local/lib/python3.10/dist-packages (from streamlit>=0.63->streamlit_chat) (4.11.0)\n",
            "Requirement already satisfied: gitpython!=3.1.19,<4,>=3.0.7 in /usr/local/lib/python3.10/dist-packages (from streamlit>=0.63->streamlit_chat) (3.1.43)\n",
            "Requirement already satisfied: pydeck<1,>=0.8.0b4 in /usr/local/lib/python3.10/dist-packages (from streamlit>=0.63->streamlit_chat) (0.8.1b0)\n",
            "Requirement already satisfied: tornado<7,>=6.0.3 in /usr/local/lib/python3.10/dist-packages (from streamlit>=0.63->streamlit_chat) (6.3.3)\n",
            "Requirement already satisfied: watchdog>=2.1.5 in /usr/local/lib/python3.10/dist-packages (from streamlit>=0.63->streamlit_chat) (4.0.0)\n",
            "Requirement already satisfied: entrypoints in /usr/local/lib/python3.10/dist-packages (from altair<6,>=4.0->streamlit>=0.63->streamlit_chat) (0.4)\n",
            "Requirement already satisfied: jinja2 in /usr/local/lib/python3.10/dist-packages (from altair<6,>=4.0->streamlit>=0.63->streamlit_chat) (3.1.3)\n",
            "Requirement already satisfied: jsonschema>=3.0 in /usr/local/lib/python3.10/dist-packages (from altair<6,>=4.0->streamlit>=0.63->streamlit_chat) (4.19.2)\n",
            "Requirement already satisfied: toolz in /usr/local/lib/python3.10/dist-packages (from altair<6,>=4.0->streamlit>=0.63->streamlit_chat) (0.12.1)\n",
            "Requirement already satisfied: gitdb<5,>=4.0.1 in /usr/local/lib/python3.10/dist-packages (from gitpython!=3.1.19,<4,>=3.0.7->streamlit>=0.63->streamlit_chat) (4.0.11)\n",
            "Requirement already satisfied: python-dateutil>=2.8.2 in /usr/local/lib/python3.10/dist-packages (from pandas<3,>=1.3.0->streamlit>=0.63->streamlit_chat) (2.8.2)\n",
            "Requirement already satisfied: pytz>=2020.1 in /usr/local/lib/python3.10/dist-packages (from pandas<3,>=1.3.0->streamlit>=0.63->streamlit_chat) (2023.4)\n",
            "Requirement already satisfied: tzdata>=2022.1 in /usr/local/lib/python3.10/dist-packages (from pandas<3,>=1.3.0->streamlit>=0.63->streamlit_chat) (2024.1)\n",
            "Requirement already satisfied: charset-normalizer<4,>=2 in /usr/local/lib/python3.10/dist-packages (from requests<3,>=2.27->streamlit>=0.63->streamlit_chat) (3.3.2)\n",
            "Requirement already satisfied: idna<4,>=2.5 in /usr/local/lib/python3.10/dist-packages (from requests<3,>=2.27->streamlit>=0.63->streamlit_chat) (3.6)\n",
            "Requirement already satisfied: urllib3<3,>=1.21.1 in /usr/local/lib/python3.10/dist-packages (from requests<3,>=2.27->streamlit>=0.63->streamlit_chat) (2.0.7)\n",
            "Requirement already satisfied: certifi>=2017.4.17 in /usr/local/lib/python3.10/dist-packages (from requests<3,>=2.27->streamlit>=0.63->streamlit_chat) (2024.2.2)\n",
            "Requirement already satisfied: markdown-it-py>=2.2.0 in /usr/local/lib/python3.10/dist-packages (from rich<14,>=10.14.0->streamlit>=0.63->streamlit_chat) (3.0.0)\n",
            "Requirement already satisfied: pygments<3.0.0,>=2.13.0 in /usr/local/lib/python3.10/dist-packages (from rich<14,>=10.14.0->streamlit>=0.63->streamlit_chat) (2.16.1)\n",
            "Requirement already satisfied: smmap<6,>=3.0.1 in /usr/local/lib/python3.10/dist-packages (from gitdb<5,>=4.0.1->gitpython!=3.1.19,<4,>=3.0.7->streamlit>=0.63->streamlit_chat) (5.0.1)\n",
            "Requirement already satisfied: MarkupSafe>=2.0 in /usr/local/lib/python3.10/dist-packages (from jinja2->altair<6,>=4.0->streamlit>=0.63->streamlit_chat) (2.1.5)\n",
            "Requirement already satisfied: attrs>=22.2.0 in /usr/local/lib/python3.10/dist-packages (from jsonschema>=3.0->altair<6,>=4.0->streamlit>=0.63->streamlit_chat) (23.2.0)\n",
            "Requirement already satisfied: jsonschema-specifications>=2023.03.6 in /usr/local/lib/python3.10/dist-packages (from jsonschema>=3.0->altair<6,>=4.0->streamlit>=0.63->streamlit_chat) (2023.12.1)\n",
            "Requirement already satisfied: referencing>=0.28.4 in /usr/local/lib/python3.10/dist-packages (from jsonschema>=3.0->altair<6,>=4.0->streamlit>=0.63->streamlit_chat) (0.34.0)\n",
            "Requirement already satisfied: rpds-py>=0.7.1 in /usr/local/lib/python3.10/dist-packages (from jsonschema>=3.0->altair<6,>=4.0->streamlit>=0.63->streamlit_chat) (0.18.0)\n",
            "Requirement already satisfied: mdurl~=0.1 in /usr/local/lib/python3.10/dist-packages (from markdown-it-py>=2.2.0->rich<14,>=10.14.0->streamlit>=0.63->streamlit_chat) (0.1.2)\n",
            "Requirement already satisfied: six>=1.5 in /usr/local/lib/python3.10/dist-packages (from python-dateutil>=2.8.2->pandas<3,>=1.3.0->streamlit>=0.63->streamlit_chat) (1.16.0)\n",
            "Installing collected packages: streamlit_chat\n",
            "Successfully installed streamlit_chat-0.1.1\n"
          ]
        }
      ]
    },
    {
      "cell_type": "code",
      "source": [
        "import streamlit as st\n",
        "import openai\n",
        "from streamlit_chat import message\n"
      ],
      "metadata": {
        "id": "TuKaeZvzFagm"
      },
      "execution_count": 10,
      "outputs": []
    },
    {
      "cell_type": "code",
      "source": [
        "import streamlit as st\n",
        "import openai\n",
        "from streamlit_chat import message\n",
        "\n",
        "st.write(\"Hello Welcome\")\n",
        "openai.api_key = \"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\"\n",
        "\n",
        "def api_calling(prompt):\n",
        "    completions = openai.Completion.create(\n",
        "        engine=\"text-davinci-003\",\n",
        "        prompt=prompt,\n",
        "        max_tokens=1024,\n",
        "        n=1,\n",
        "        stop=None,\n",
        "        temperature=0.5,\n",
        "    )\n",
        "    message = completions.choices[0].text\n",
        "    return message\n",
        "\n",
        "st.title(\"ChatGPT ChatBot With Streamlit and OpenAI\")\n",
        "\n",
        "user_input = st.text_input(\"Write here\")\n",
        "\n",
        "# Get or initialize session state variables\n",
        "user_input_history = st.session_state.get('user_input', [])\n",
        "openai_response_history = st.session_state.get('openai_response', [])\n",
        "\n",
        "if user_input:\n",
        "    output = api_calling(user_input)\n",
        "    output = output.lstrip(\"\\n\")\n",
        "\n",
        "    # Update session state variables\n",
        "    user_input_history.append(user_input)\n",
        "    openai_response_history.append(output)\n",
        "\n",
        "message_history = st.empty()\n",
        "\n",
        "if user_input_history:\n",
        "    for i in range(len(user_input_history) - 1, -1, -1):\n",
        "        # This function displays user input\n",
        "        message(user_input_history[i],\n",
        "                key=str(i), avatar_style=\"icons\")\n",
        "        # This function displays OpenAI response\n",
        "        message(openai_response_history[i],\n",
        "                avatar_style=\"miniavs\", is_user=True,\n",
        "                key=str(i) + 'data_by_user')\n"
      ],
      "metadata": {
        "id": "kQnwxa1WFY3q"
      },
      "execution_count": 13,
      "outputs": []
    }
  ]
}